2019-01-30 16:59:05,279 - luigi-interface - DEBUG - Checking if main.runMe() is complete
2019-01-30 16:59:05,280 - luigi-interface - DEBUG - Checking if main.execution() is complete
2019-01-30 16:59:05,280 - luigi-interface - INFO - Informed scheduler that task   main.runMe__99914b932b   has status   PENDING
2019-01-30 16:59:05,280 - luigi-interface - INFO - Informed scheduler that task   main.execution__99914b932b   has status   PENDING
2019-01-30 16:59:05,280 - luigi-interface - INFO - Done scheduling tasks
2019-01-30 16:59:05,281 - luigi-interface - INFO - Running Worker with 1 processes
2019-01-30 16:59:05,281 - luigi-interface - DEBUG - Asking scheduler for work...
2019-01-30 16:59:05,281 - luigi-interface - DEBUG - Pending tasks: 2
2019-01-30 16:59:05,281 - luigi-interface - INFO - [pid 63200] Worker Worker(salt=563962852, workers=1, host=Robsons-MacBook-Pro-2.local, username=poffo, pid=63200) running   main.execution()
2019-01-30 16:59:05,542 - luigi-interface - ERROR - [pid 63200] Worker Worker(salt=563962852, workers=1, host=Robsons-MacBook-Pro-2.local, username=poffo, pid=63200) failed    main.execution()
Traceback (most recent call last):
  File "/anaconda3/envs/pycarol/lib/python3.7/site-packages/luigi/worker.py", line 199, in run
    new_deps = self._run_get_new_deps()
  File "/anaconda3/envs/pycarol/lib/python3.7/site-packages/luigi/worker.py", line 139, in _run_get_new_deps
    task_gen = self.task.run()
  File "/Users/poffo/Dropbox/hd/trabalhos/totvslabs/_developments/workspaceAI/carolapp-samples/batch-carolapp/ai-script/test_script.py", line 51, in run
    connector = connectors.get_by_name("carolml")
  File "/Users/poffo/Dropbox/hd/trabalhos/totvslabs/_developments/workspaceAI/carolapp-samples/batch-carolapp/ai-script/pycarol/connectors.py", line 52, in get_by_name
    resp = self.carol.call_api('v1/connectors/name/{}'.format(name))
  File "/Users/poffo/Dropbox/hd/trabalhos/totvslabs/_developments/workspaceAI/carolapp-samples/batch-carolapp/ai-script/pycarol/carol.py", line 217, in call_api
    raise Exception(response.text)
Exception: {"errorCode":400,"errorMessage":"apiKey and connectorId pair is invalid.","possibleResponsibleField":""}
2019-01-30 16:59:05,546 - luigi-interface - DEBUG - 1 running tasks, waiting for next task to finish
2019-01-30 16:59:05,548 - luigi-interface - INFO - Informed scheduler that task   main.execution__99914b932b   has status   FAILED
2019-01-30 16:59:05,548 - luigi-interface - DEBUG - Asking scheduler for work...
2019-01-30 16:59:05,549 - luigi-interface - DEBUG - Done
2019-01-30 16:59:05,549 - luigi-interface - DEBUG - There are no more tasks to run at this time
2019-01-30 16:59:05,549 - luigi-interface - DEBUG - There are 2 pending tasks possibly being run by other workers
2019-01-30 16:59:05,549 - luigi-interface - DEBUG - There are 2 pending tasks unique to this worker
2019-01-30 16:59:05,549 - luigi-interface - DEBUG - There are 2 pending tasks last scheduled by this worker
2019-01-30 16:59:05,549 - luigi-interface - INFO - Worker Worker(salt=563962852, workers=1, host=Robsons-MacBook-Pro-2.local, username=poffo, pid=63200) was stopped. Shutting down Keep-Alive thread
2019-01-30 16:59:05,550 - luigi-interface - INFO - 
===== Luigi Execution Summary =====

Scheduled 2 tasks of which:
* 1 failed:
    - 1 main.execution()
* 1 were left pending, among these:
    * 1 had failed dependencies:
        - 1 main.runMe()

This progress looks :( because there were failed tasks

===== Luigi Execution Summary =====

2019-01-30 17:01:30,373 - luigi-interface - DEBUG - Checking if main.runMe() is complete
2019-01-30 17:01:30,374 - luigi-interface - DEBUG - Checking if main.execution() is complete
2019-01-30 17:01:30,375 - luigi-interface - INFO - Informed scheduler that task   main.runMe__99914b932b   has status   PENDING
2019-01-30 17:01:30,376 - luigi-interface - INFO - Informed scheduler that task   main.execution__99914b932b   has status   PENDING
2019-01-30 17:01:30,376 - luigi-interface - INFO - Done scheduling tasks
2019-01-30 17:01:30,376 - luigi-interface - INFO - Running Worker with 1 processes
2019-01-30 17:01:30,376 - luigi-interface - DEBUG - Asking scheduler for work...
2019-01-30 17:01:30,377 - luigi-interface - DEBUG - Pending tasks: 2
2019-01-30 17:01:30,377 - luigi-interface - INFO - [pid 65714] Worker Worker(salt=602350210, workers=1, host=Robsons-MacBook-Pro-2.local, username=poffo, pid=65714) running   main.execution()
2019-01-30 17:01:30,631 - luigi-interface - ERROR - [pid 65714] Worker Worker(salt=602350210, workers=1, host=Robsons-MacBook-Pro-2.local, username=poffo, pid=65714) failed    main.execution()
Traceback (most recent call last):
  File "/anaconda3/envs/pycarol/lib/python3.7/site-packages/luigi/worker.py", line 199, in run
    new_deps = self._run_get_new_deps()
  File "/anaconda3/envs/pycarol/lib/python3.7/site-packages/luigi/worker.py", line 139, in _run_get_new_deps
    task_gen = self.task.run()
  File "/Users/poffo/Dropbox/hd/trabalhos/totvslabs/_developments/workspaceAI/carolapp-samples/batch-carolapp/ai-script/test_script.py", line 51, in run
    connector = connectors.get_by_name("carolml")
  File "/Users/poffo/Dropbox/hd/trabalhos/totvslabs/_developments/workspaceAI/carolapp-samples/batch-carolapp/ai-script/pycarol/connectors.py", line 52, in get_by_name
    resp = self.carol.call_api('v1/connectors/name/{}'.format(name))
  File "/Users/poffo/Dropbox/hd/trabalhos/totvslabs/_developments/workspaceAI/carolapp-samples/batch-carolapp/ai-script/pycarol/carol.py", line 217, in call_api
    raise Exception(response.text)
Exception: {"errorCode":400,"errorMessage":"apiKey and connectorId pair is invalid.","possibleResponsibleField":""}
2019-01-30 17:01:30,635 - luigi-interface - DEBUG - 1 running tasks, waiting for next task to finish
2019-01-30 17:01:30,638 - luigi-interface - INFO - Informed scheduler that task   main.execution__99914b932b   has status   FAILED
2019-01-30 17:01:30,638 - luigi-interface - DEBUG - Asking scheduler for work...
2019-01-30 17:01:30,638 - luigi-interface - DEBUG - Done
2019-01-30 17:01:30,638 - luigi-interface - DEBUG - There are no more tasks to run at this time
2019-01-30 17:01:30,638 - luigi-interface - DEBUG - There are 2 pending tasks possibly being run by other workers
2019-01-30 17:01:30,638 - luigi-interface - DEBUG - There are 2 pending tasks unique to this worker
2019-01-30 17:01:30,638 - luigi-interface - DEBUG - There are 2 pending tasks last scheduled by this worker
2019-01-30 17:01:30,638 - luigi-interface - INFO - Worker Worker(salt=602350210, workers=1, host=Robsons-MacBook-Pro-2.local, username=poffo, pid=65714) was stopped. Shutting down Keep-Alive thread
2019-01-30 17:01:30,639 - luigi-interface - INFO - 
===== Luigi Execution Summary =====

Scheduled 2 tasks of which:
* 1 failed:
    - 1 main.execution()
* 1 were left pending, among these:
    * 1 had failed dependencies:
        - 1 main.runMe()

This progress looks :( because there were failed tasks

===== Luigi Execution Summary =====

2019-01-30 23:51:51,057 - luigi-interface - DEBUG - Checking if main.runMe() is complete
2019-01-30 23:51:51,058 - luigi-interface - DEBUG - Checking if main.execution() is complete
2019-01-30 23:51:51,059 - luigi-interface - INFO - Informed scheduler that task   main.runMe__99914b932b   has status   PENDING
2019-01-30 23:51:51,059 - luigi-interface - INFO - Informed scheduler that task   main.execution__99914b932b   has status   PENDING
2019-01-30 23:51:51,059 - luigi-interface - INFO - Done scheduling tasks
2019-01-30 23:51:51,059 - luigi-interface - INFO - Running Worker with 1 processes
2019-01-30 23:51:51,060 - luigi-interface - DEBUG - Asking scheduler for work...
2019-01-30 23:51:51,060 - luigi-interface - DEBUG - Pending tasks: 2
2019-01-30 23:51:51,060 - luigi-interface - INFO - [pid 25112] Worker Worker(salt=410280178, workers=1, host=Robsons-MacBook-Pro-2.local, username=poffo, pid=25112) running   main.execution()
2019-01-30 23:51:51,348 - luigi-interface - ERROR - [pid 25112] Worker Worker(salt=410280178, workers=1, host=Robsons-MacBook-Pro-2.local, username=poffo, pid=25112) failed    main.execution()
Traceback (most recent call last):
  File "/anaconda3/envs/pycarol/lib/python3.7/site-packages/luigi/worker.py", line 199, in run
    new_deps = self._run_get_new_deps()
  File "/anaconda3/envs/pycarol/lib/python3.7/site-packages/luigi/worker.py", line 139, in _run_get_new_deps
    task_gen = self.task.run()
  File "/Users/poffo/Dropbox/hd/trabalhos/totvslabs/_developments/workspaceAI/carolapp-samples/batch-carolapp/ai-script/test_script.py", line 51, in run
    connector = connectors.get_by_name("carolml")
  File "/Users/poffo/Dropbox/hd/trabalhos/totvslabs/_developments/workspaceAI/carolapp-samples/batch-carolapp/ai-script/pycarol/connectors.py", line 52, in get_by_name
    resp = self.carol.call_api('v1/connectors/name/{}'.format(name))
  File "/Users/poffo/Dropbox/hd/trabalhos/totvslabs/_developments/workspaceAI/carolapp-samples/batch-carolapp/ai-script/pycarol/carol.py", line 236, in call_api
    raise Exception(response.text)
Exception: {"errorCode":400,"errorMessage":"apiKey and connectorId pair is invalid.","possibleResponsibleField":""}
2019-01-30 23:51:51,352 - luigi-interface - DEBUG - 1 running tasks, waiting for next task to finish
2019-01-30 23:51:51,354 - luigi-interface - INFO - Informed scheduler that task   main.execution__99914b932b   has status   FAILED
2019-01-30 23:51:51,355 - luigi-interface - DEBUG - Asking scheduler for work...
2019-01-30 23:51:51,355 - luigi-interface - DEBUG - Done
2019-01-30 23:51:51,355 - luigi-interface - DEBUG - There are no more tasks to run at this time
2019-01-30 23:51:51,355 - luigi-interface - DEBUG - There are 2 pending tasks possibly being run by other workers
2019-01-30 23:51:51,355 - luigi-interface - DEBUG - There are 2 pending tasks unique to this worker
2019-01-30 23:51:51,355 - luigi-interface - DEBUG - There are 2 pending tasks last scheduled by this worker
2019-01-30 23:51:51,355 - luigi-interface - INFO - Worker Worker(salt=410280178, workers=1, host=Robsons-MacBook-Pro-2.local, username=poffo, pid=25112) was stopped. Shutting down Keep-Alive thread
2019-01-30 23:51:51,356 - luigi-interface - INFO - 
===== Luigi Execution Summary =====

Scheduled 2 tasks of which:
* 1 failed:
    - 1 main.execution()
* 1 were left pending, among these:
    * 1 had failed dependencies:
        - 1 main.runMe()

This progress looks :( because there were failed tasks

===== Luigi Execution Summary =====

2019-01-30 23:53:09,591 - luigi-interface - DEBUG - Checking if main.runMe() is complete
2019-01-30 23:53:09,592 - luigi-interface - DEBUG - Checking if main.execution() is complete
2019-01-30 23:53:09,593 - luigi-interface - INFO - Informed scheduler that task   main.runMe__99914b932b   has status   PENDING
2019-01-30 23:53:09,593 - luigi-interface - INFO - Informed scheduler that task   main.execution__99914b932b   has status   PENDING
2019-01-30 23:53:09,593 - luigi-interface - INFO - Done scheduling tasks
2019-01-30 23:53:09,593 - luigi-interface - INFO - Running Worker with 1 processes
2019-01-30 23:53:09,593 - luigi-interface - DEBUG - Asking scheduler for work...
2019-01-30 23:53:09,594 - luigi-interface - DEBUG - Pending tasks: 2
2019-01-30 23:53:09,594 - luigi-interface - INFO - [pid 26395] Worker Worker(salt=892820473, workers=1, host=Robsons-MacBook-Pro-2.local, username=poffo, pid=26395) running   main.execution()
2019-01-30 23:53:10,465 - luigi-interface - INFO - [pid 26395] Worker Worker(salt=892820473, workers=1, host=Robsons-MacBook-Pro-2.local, username=poffo, pid=26395) done      main.execution()
2019-01-30 23:53:10,466 - luigi-interface - DEBUG - 1 running tasks, waiting for next task to finish
2019-01-30 23:53:10,467 - luigi-interface - INFO - Informed scheduler that task   main.execution__99914b932b   has status   DONE
2019-01-30 23:53:10,467 - luigi-interface - DEBUG - Asking scheduler for work...
2019-01-30 23:53:10,467 - luigi-interface - DEBUG - Pending tasks: 1
2019-01-30 23:53:10,467 - luigi-interface - INFO - [pid 26395] Worker Worker(salt=892820473, workers=1, host=Robsons-MacBook-Pro-2.local, username=poffo, pid=26395) running   main.runMe()
2019-01-30 23:53:10,468 - luigi-interface - INFO - [pid 26395] Worker Worker(salt=892820473, workers=1, host=Robsons-MacBook-Pro-2.local, username=poffo, pid=26395) done      main.runMe()
2019-01-30 23:53:10,468 - luigi-interface - DEBUG - 1 running tasks, waiting for next task to finish
2019-01-30 23:53:10,468 - luigi-interface - INFO - Informed scheduler that task   main.runMe__99914b932b   has status   DONE
2019-01-30 23:53:10,468 - luigi-interface - DEBUG - Asking scheduler for work...
2019-01-30 23:53:10,468 - luigi-interface - DEBUG - Done
2019-01-30 23:53:10,468 - luigi-interface - DEBUG - There are no more tasks to run at this time
2019-01-30 23:53:10,468 - luigi-interface - INFO - Worker Worker(salt=892820473, workers=1, host=Robsons-MacBook-Pro-2.local, username=poffo, pid=26395) was stopped. Shutting down Keep-Alive thread
2019-01-30 23:53:10,469 - luigi-interface - INFO - 
===== Luigi Execution Summary =====

Scheduled 2 tasks of which:
* 2 ran successfully:
    - 1 main.execution()
    - 1 main.runMe()

This progress looks :) because there were no failed tasks or missing dependencies

===== Luigi Execution Summary =====

